Workbook

Sheet Overview
B1: Money Report
B3: =TEXT(About!C4,"mmmm yyyy")&" · SAMPLE DATA, all names and amounts are fake" | K3: As of | L3: =About!$C$4
B5: INCOME | D5: TOTAL SPENT | F5: NET CASH FLOW | H5: LENT OUTSTANDING | J5: CARD DUES ≤ 7 DAYS | L5: AWAITING YOU
B6: =SUMIFS(Ledger!$F$2:$F$200,Ledger!$H$2:$H$200,"Income",Ledger!$B$2:$B$200,">="&About!$C$5,Ledger!$B$2:$B$200,"<="&About!$C$6) | D6: =SUMIFS(Ledger!$N$2:$N$200,Ledger!$B$2:$B$200,">="&About!$C$5,Ledger!$B$2:$B$200,"<="&About!$C$6) | F6: =B6-D6 | H6: ='People & Lent'!$J$13 | J6: ='Cards & Dues'!$H$9 | L6: ='People & Lent'!$J$14
B7: =COUNTIFS(Ledger!$H$2:$H$200,"Income",Ledger!$B$2:$B$200,">="&About!$C$5,Ledger!$B$2:$B$200,"<="&About!$C$6)&" credits" | D7: =COUNTIFS(Ledger!$N$2:$N$200,"<>0",Ledger!$B$2:$B$200,">="&About!$C$5,Ledger!$B$2:$B$200,"<="&About!$C$6)&" transactions" | F7: =IF(B6=0,"",TEXT(F6/B6,"0%")&" of income kept") | H7: =COUNTIF('People & Lent'!$J$7:$J$11,">0")&" open" | J7: =COUNTIFS('Cards & Dues'!$F$6:$F$7,">=0",'Cards & Dues'!$F$6:$F$7,"<=7",'Cards & Dues'!$H$6:$H$7,">0")&" card(s)" | L7: =COUNTIF(Ledger!$H$2:$H$200,"Undecided")&" payment(s) undecided"
B9: Where the spending went | I9: Spending by week
B10: Block | C10: Amount | D10: Share | I10: Week | J10: Days | K10: Spent | L10: Trend
B11: Credit card | C11: =SUMIFS(Ledger!$N$2:$N$200,Ledger!$H$2:$H$200,"CC Spend",Ledger!$B$2:$B$200,">="&About!$C$5,Ledger!$B$2:$B$200,"<="&About!$C$6) | D11: =IF($C$15=0,0,C11/$C$15) | E11: =REPT("█",ROUND(D11*18,0)) | I11: Week 1 | J11: ="1–7" | K11: =SUMIFS(Ledger!$N$2:$N$200,Ledger!$B$2:$B$200,">="&DATE(YEAR(About!$C$5),MONTH(About!$C$5),1),Ledger!$B$2:$B$200,"<="&MIN(DATE(YEAR(About!$C$5),MONTH(About!$C$5),7),About!$C$6)) | L11: =REPT("█",ROUND(IF(MAX($K$11:$K$15)=0,0,K11/MAX($K$11:$K$15)*10),0))
B12: Bank | C12: =SUMIFS(Ledger!$N$2:$N$200,Ledger!$H$2:$H$200,"Bank Spend",Ledger!$B$2:$B$200,">="&About!$C$5,Ledger!$B$2:$B$200,"<="&About!$C$6) | D12: =IF($C$15=0,0,C12/$C$15) | E12: =REPT("█",ROUND(D12*18,0)) | I12: Week 2 | J12: ="8–14" | K12: =SUMIFS(Ledger!$N$2:$N$200,Ledger!$B$2:$B$200,">="&DATE(YEAR(About!$C$5),MONTH(About!$C$5),8),Ledger!$B$2:$B$200,"<="&MIN(DATE(YEAR(About!$C$5),MONTH(About!$C$5),14),About!$C$6)) | L12: =REPT("█",ROUND(IF(MAX($K$11:$K$15)=0,0,K12/MAX($K$11:$K$15)*10),0))
B13: Regular | C13: =SUMIFS(Ledger!$N$2:$N$200,Ledger!$H$2:$H$200,"Regular",Ledger!$B$2:$B$200,">="&About!$C$5,Ledger!$B$2:$B$200,"<="&About!$C$6) | D13: =IF($C$15=0,0,C13/$C$15) | E13: =REPT("█",ROUND(D13*18,0)) | I13: Week 3 | J13: ="15–21" | K13: =SUMIFS(Ledger!$N$2:$N$200,Ledger!$B$2:$B$200,">="&DATE(YEAR(About!$C$5),MONTH(About!$C$5),15),Ledger!$B$2:$B$200,"<="&MIN(DATE(YEAR(About!$C$5),MONTH(About!$C$5),21),About!$C$6)) | L13: =REPT("█",ROUND(IF(MAX($K$11:$K$15)=0,0,K13/MAX($K$11:$K$15)*10),0))
B14: EMI | C14: =SUMIFS(Ledger!$N$2:$N$200,Ledger!$H$2:$H$200,"EMI",Ledger!$B$2:$B$200,">="&About!$C$5,Ledger!$B$2:$B$200,"<="&About!$C$6) | D14: =IF($C$15=0,0,C14/$C$15) | E14: =REPT("█",ROUND(D14*18,0)) | I14: Week 4 | J14: ="22–28" | K14: =SUMIFS(Ledger!$N$2:$N$200,Ledger!$B$2:$B$200,">="&DATE(YEAR(About!$C$5),MONTH(About!$C$5),22),Ledger!$B$2:$B$200,"<="&MIN(DATE(YEAR(About!$C$5),MONTH(About!$C$5),28),About!$C$6)) | L14: =REPT("█",ROUND(IF(MAX($K$11:$K$15)=0,0,K14/MAX($K$11:$K$15)*10),0))
B15: Total spent | C15: =SUM(C11:C14) | D15: =SUM(D11:D14) | I15: Week 5 | J15: ="29–31" | K15: =SUMIFS(Ledger!$N$2:$N$200,Ledger!$B$2:$B$200,">="&DATE(YEAR(About!$C$5),MONTH(About!$C$5),29),Ledger!$B$2:$B$200,"<="&MIN(DATE(YEAR(About!$C$5),MONTH(About!$C$5),31),About!$C$6)) | L15: =REPT("█",ROUND(IF(MAX($K$11:$K$15)=0,0,K15/MAX($K$11:$K$15)*10),0))
B16: Check: equals the Total spent card | C16: =IF(ROUND(C15-D6,2)=0,"OK","MISMATCH") | I16: Highest week | K16: ="Week "&MATCH(MAX(K11:K15),K11:K15,0)
B18: Moved between your own accounts
B19: Transfers (each counted once) | E19: =SUMIFS(Ledger!$F$2:$F$200,Ledger!$H$2:$H$200,"Transfer",Ledger!$E$2:$E$200,"Debit",Ledger!$B$2:$B$200,">="&About!$C$5,Ledger!$B$2:$B$200,"<="&About!$C$6) | F19: Not income, not spending. Both legs stay in each account's history.
B20: Card bills paid from banks | E20: =SUMIFS(Ledger!$F$2:$F$200,Ledger!$H$2:$H$200,"Card bill",Ledger!$B$2:$B$200,">="&About!$C$5,Ledger!$B$2:$B$200,"<="&About!$C$6) | F20: Settles card liability. Purchases were counted when charged.
B22: Coverage and disclosures
B23: ● | C23: ="Needs attention: "&5&" item(s), see the Review sheet"
B24: ● | C24: ="Awaiting your decision: "&TEXT(L6,"₹#,##0")&" (not in spending or lent until you choose)"
B25: ● | C25: ="Transfer legs not matched: "&TEXT('Money Map'!E20,"₹#,##0")&" (credit SMS not seen)"
B26: ● | C26: ="Accounts reporting: 6 of 6 · last SMS 30-Oct-26 (sample)"

Sheet Money Map
B1: Money Map
B3: Where the salary went this month: in, moved to your other accounts, spent. Transfers are counted once and are not spending.
B5: Salary flow (HDFC) | C5: Amount | D5: Share of salary
B6: Salary in | C6: =SUMIFS(Ledger!$F$2:$F$200,Ledger!$G$2:$G$200,"Salary",Ledger!$B$2:$B$200,">="&About!$C$5,Ledger!$B$2:$B$200,"<="&About!$C$6) | D6: =IF($C$6=0,0,C6/$C$6) | E6: =REPT("█",ROUND(D6*24,0))
B7: Moved to other accounts | C7: =SUMIFS(Ledger!$F$2:$F$200,Ledger!$C$2:$C$200,"HDFC ••7345",Ledger!$H$2:$H$200,"Transfer",Ledger!$E$2:$E$200,"Debit",Ledger!$B$2:$B$200,">="&About!$C$5,Ledger!$B$2:$B$200,"<="&About!$C$6) | D7: =IF($C$6=0,0,C7/$C$6) | E7: =REPT("█",ROUND(D7*24,0))
B8: Spent from this account | C8: =SUMIFS(Ledger!$N$2:$N$200,Ledger!$C$2:$C$200,"HDFC ••7345",Ledger!$B$2:$B$200,">="&About!$C$5,Ledger!$B$2:$B$200,"<="&About!$C$6) | D8: =IF($C$6=0,0,C8/$C$6) | E8: =REPT("█",ROUND(D8*24,0))
B9: Left from this month's salary | C9: =C6-C7-C8 | D9: =IF($C$6=0,0,C9/$C$6) | E9: =REPT("█",ROUND(D9*24,0))
B12: Account | C12: Income in | D12: Transfers in | E12: Transfers out | F12: Spent | G12: Lent + undecided | H12: Card bills paid | I12: Net change
B13: HDFC ••7345 | C13: =SUMIFS(Ledger!$F$2:$F$200,Ledger!$C$2:$C$200,B13,Ledger!$H$2:$H$200,"Income",Ledger!$B$2:$B$200,">="&About!$C$5,Ledger!$B$2:$B$200,"<="&About!$C$6) | D13: =SUMIFS(Ledger!$F$2:$F$200,Ledger!$C$2:$C$200,B13,Ledger!$H$2:$H$200,"Transfer",Ledger!$E$2:$E$200,"Credit",Ledger!$B$2:$B$200,">="&About!$C$5,Ledger!$B$2:$B$200,"<="&About!$C$6) | E13: =SUMIFS(Ledger!$F$2:$F$200,Ledger!$C$2:$C$200,B13,Ledger!$H$2:$H$200,"Transfer",Ledger!$E$2:$E$200,"Debit",Ledger!$B$2:$B$200,">="&About!$C$5,Ledger!$B$2:$B$200,"<="&About!$C$6) | F13: =SUMIFS(Ledger!$N$2:$N$200,Ledger!$C$2:$C$200,B13,Ledger!$B$2:$B$200,">="&About!$C$5,Ledger!$B$2:$B$200,"<="&About!$C$6) | G13: =SUMIFS(Ledger!$F$2:$F$200,Ledger!$C$2:$C$200,B13,Ledger!$H$2:$H$200,"Lent",Ledger!$B$2:$B$200,">="&About!$C$5,Ledger!$B$2:$B$200,"<="&About!$C$6)+SUMIFS(Ledger!$F$2:$F$200,Ledger!$C$2:$C$200,B13,Ledger!$H$2:$H$200,"Undecided",Ledger!$B$2:$B$200,">="&About!$C$5,Ledger!$B$2:$B$200,"<="&About!$C$6)-SUMIFS(Ledger!$F$2:$F$200,Ledger!$C$2:$C$200,B13,Ledger!$H$2:$H$200,"Lent repayment",Ledger!$B$2:$B$200,">="&About!$C$5,Ledger!$B$2:$B$200,"<="&About!$C$6) | H13: =SUMIFS(Ledger!$F$2:$F$200,Ledger!$C$2:$C$200,B13,Ledger!$H$2:$H$200,"Card bill",Ledger!$B$2:$B$200,">="&About!$C$5,Ledger!$B$2:$B$200,"<="&About!$C$6) | I13: =C13+D13-E13-F13-G13-H13
B14: Kotak ••2126 | C14: =SUMIFS(Ledger!$F$2:$F$200,Ledger!$C$2:$C$200,B14,Ledger!$H$2:$H$200,"Income",Ledger!$B$2:$B$200,">="&About!$C$5,Ledger!$B$2:$B$200,"<="&About!$C$6) | D14: =SUMIFS(Ledger!$F$2:$F$200,Ledger!$C$2:$C$200,B14,Ledger!$H$2:$H$200,"Transfer",Ledger!$E$2:$E$200,"Credit",Ledger!$B$2:$B$200,">="&About!$C$5,Ledger!$B$2:$B$200,"<="&About!$C$6) | E14: =SUMIFS(Ledger!$F$2:$F$200,Ledger!$C$2:$C$200,B14,Ledger!$H$2:$H$200,"Transfer",Ledger!$E$2:$E$200,"Debit",Ledger!$B$2:$B$200,">="&About!$C$5,Ledger!$B$2:$B$200,"<="&About!$C$6) | F14: =SUMIFS(Ledger!$N$2:$N$200,Ledger!$C$2:$C$200,B14,Ledger!$B$2:$B$200,">="&About!$C$5,Ledger!$B$2:$B$200,"<="&About!$C$6) | G14: =SUMIFS(Ledger!$F$2:$F$200,Ledger!$C$2:$C$200,B14,Ledger!$H$2:$H$200,"Lent",Ledger!$B$2:$B$200,">="&About!$C$5,Ledger!$B$2:$B$200,"<="&About!$C$6)+SUMIFS(Ledger!$F$2:$F$200,Ledger!$C$2:$C$200,B14,Ledger!$H$2:$H$200,"Undecided",Ledger!$B$2:$B$200,">="&About!$C$5,Ledger!$B$2:$B$200,"<="&About!$C$6)-SUMIFS(Ledger!$F$2:$F$200,Ledger!$C$2:$C$200,B14,Ledger!$H$2:$H$200,"Lent repayment",Ledger!$B$2:$B$200,">="&About!$C$5,Ledger!$B$2:$B$200,"<="&About!$C$6) | H14: =SUMIFS(Ledger!$F$2:$F$200,Ledger!$C$2:$C$200,B14,Ledger!$H$2:$H$200,"Card bill",Ledger!$B$2:$B$200,">="&About!$C$5,Ledger!$B$2:$B$200,"<="&About!$C$6) | I14: =C14+D14-E14-F14-G14-H14
B15: Federal ••3268 | C15: =SUMIFS(Ledger!$F$2:$F$200,Ledger!$C$2:$C$200,B15,Ledger!$H$2:$H$200,"Income",Ledger!$B$2:$B$200,">="&About!$C$5,Ledger!$B$2:$B$200,"<="&About!$C$6) | D15: =SUMIFS(Ledger!$F$2:$F$200,Ledger!$C$2:$C$200,B15,Ledger!$H$2:$H$200,"Transfer",Ledger!$E$2:$E$200,"Credit",Ledger!$B$2:$B$200,">="&About!$C$5,Ledger!$B$2:$B$200,"<="&About!$C$6) | E15: =SUMIFS(Ledger!$F$2:$F$200,Ledger!$C$2:$C$200,B15,Ledger!$H$2:$H$200,"Transfer",Ledger!$E$2:$E$200,"Debit",Ledger!$B$2:$B$200,">="&About!$C$5,Ledger!$B$2:$B$200,"<="&About!$C$6) | F15: =SUMIFS(Ledger!$N$2:$N$200,Ledger!$C$2:$C$200,B15,Ledger!$B$2:$B$200,">="&About!$C$5,Ledger!$B$2:$B$200,"<="&About!$C$6) | G15: =SUMIFS(Ledger!$F$2:$F$200,Ledger!$C$2:$C$200,B15,Ledger!$H$2:$H$200,"Lent",Ledger!$B$2:$B$200,">="&About!$C$5,Ledger!$B$2:$B$200,"<="&About!$C$6)+SUMIFS(Ledger!$F$2:$F$200,Ledger!$C$2:$C$200,B15,Ledger!$H$2:$H$200,"Undecided",Ledger!$B$2:$B$200,">="&About!$C$5,Ledger!$B$2:$B$200,"<="&About!$C$6)-SUMIFS(Ledger!$F$2:$F$200,Ledger!$C$2:$C$200,B15,Ledger!$H$2:$H$200,"Lent repayment",Ledger!$B$2:$B$200,">="&About!$C$5,Ledger!$B$2:$B$200,"<="&About!$C$6) | H15: =SUMIFS(Ledger!$F$2:$F$200,Ledger!$C$2:$C$200,B15,Ledger!$H$2:$H$200,"Card bill",Ledger!$B$2:$B$200,">="&About!$C$5,Ledger!$B$2:$B$200,"<="&About!$C$6) | I15: =C15+D15-E15-F15-G15-H15
B16: CUB ••1756 | C16: =SUMIFS(Ledger!$F$2:$F$200,Ledger!$C$2:$C$200,B16,Ledger!$H$2:$H$200,"Income",Ledger!$B$2:$B$200,">="&About!$C$5,Ledger!$B$2:$B$200,"<="&About!$C$6) | D16: =SUMIFS(Ledger!$F$2:$F$200,Ledger!$C$2:$C$200,B16,Ledger!$H$2:$H$200,"Transfer",Ledger!$E$2:$E$200,"Credit",Ledger!$B$2:$B$200,">="&About!$C$5,Ledger!$B$2:$B$200,"<="&About!$C$6) | E16: =SUMIFS(Ledger!$F$2:$F$200,Ledger!$C$2:$C$200,B16,Ledger!$H$2:$H$200,"Transfer",Ledger!$E$2:$E$200,"Debit",Ledger!$B$2:$B$200,">="&About!$C$5,Ledger!$B$2:$B$200,"<="&About!$C$6) | F16: =SUMIFS(Ledger!$N$2:$N$200,Ledger!$C$2:$C$200,B16,Ledger!$B$2:$B$200,">="&About!$C$5,Ledger!$B$2:$B$200,"<="&About!$C$6) | G16: =SUMIFS(Ledger!$F$2:$F$200,Ledger!$C$2:$C$200,B16,Ledger!$H$2:$H$200,"Lent",Ledger!$B$2:$B$200,">="&About!$C$5,Ledger!$B$2:$B$200,"<="&About!$C$6)+SUMIFS(Ledger!$F$2:$F$200,Ledger!$C$2:$C$200,B16,Ledger!$H$2:$H$200,"Undecided",Ledger!$B$2:$B$200,">="&About!$C$5,Ledger!$B$2:$B$200,"<="&About!$C$6)-SUMIFS(Ledger!$F$2:$F$200,Ledger!$C$2:$C$200,B16,Ledger!$H$2:$H$200,"Lent repayment",Ledger!$B$2:$B$200,">="&About!$C$5,Ledger!$B$2:$B$200,"<="&About!$C$6) | H16: =SUMIFS(Ledger!$F$2:$F$200,Ledger!$C$2:$C$200,B16,Ledger!$H$2:$H$200,"Card bill",Ledger!$B$2:$B$200,">="&About!$C$5,Ledger!$B$2:$B$200,"<="&About!$C$6) | I16: =C16+D16-E16-F16-G16-H16
B17: All accounts | C17: =SUM(C13:C16) | D17: =SUM(D13:D16) | E17: =SUM(E13:E16) | F17: =SUM(F13:F16) | G17: =SUM(G13:G16) | H17: =SUM(H13:H16) | I17: =SUM(I13:I16)
B18: Transfers in and out differ by the amounts whose other leg was not seen. This is disclosed, never absorbed.
B19: Lent + undecided is net of repayments received. Net change is this month's movement, not an account balance.
B20: Transfers not matched (in minus out) | E20: =D17-E17

Sheet Cards & Dues
B1: Cards & Dues
B3: Due date drives the red "Billed tomorrow" list. A bill stays here until paid; payments you assign to a card reduce what is still due.
B5: Card | C5: Statement total | D5: Minimum due | E5: Due date | F5: Days left | G5: Paid so far | H5: Still due | I5: Status | J5: Note
B6: ICICI CC ••9000 | C6: 11020.4 | D6: 3700 | E6: 46326 | F6: =E6-About!$C$4 | G6: =SUMIFS(Ledger!$F$2:$F$200,Ledger!$M$2:$M$200,B6,Ledger!$H$2:$H$200,"Card bill") | H6: =MAX(C6-G6,0) | I6: =IF(H6<=0,"Paid",IF(F6<0,"Overdue",IF(F6=0,"Due today",IF(F6=1,"Due tomorrow",IF(F6<=7,"Due soon","Upcoming"))))) | J6: Paid ₹9,261.34 via CRED, issuer confirmation not received yet
B7: SBI CC ••8100 | C7: 18250 | D7: 365 | E7: 46335 | F7: =E7-About!$C$4 | G7: =SUMIFS(Ledger!$F$2:$F$200,Ledger!$M$2:$M$200,B7,Ledger!$H$2:$H$200,"Card bill") | H7: =MAX(C7-G7,0) | I7: =IF(H7<=0,"Paid",IF(F7<0,"Overdue",IF(F7=0,"Due today",IF(F7=1,"Due tomorrow",IF(F7<=7,"Due soon","Upcoming"))))) | J7: No payment recorded
B9: Due within 7 days (still due) | H9: =SUMIFS(H6:H7,F6:F7,">=0",F6:F7,"<=7")
B10: Card purchases are counted when charged (Overview, CC Spend). Paying the bill is never counted as spending.

Sheet People & Lent
B1: People & Lent
B3: Every UPI payment to a person is tracked. Pick Spend, Lent or Undecided in the State column (blue).
B4: Auto-spend threshold (app setting) | E4: 1000
B6: Ledger | C6: Date | D6: Person | E6: UPI id, or name + ref | F6: From account | G6: Amount | H6: State | I6: Repaid | J6: Outstanding | K6: Age (days) | L6: Next step
B7: =Ledger!A21 | C7: =Ledger!B21 | D7: =Ledger!J21 | E7: Name only · UPI ref U-6001 | F7: =Ledger!C21 | G7: =Ledger!F21 | H7: Lent | I7: =SUMIFS(Ledger!$F$2:$F$200,Ledger!$H$2:$H$200,"Lent repayment",Ledger!$J$2:$J$200,D7) | J7: =IF(H7="Lent",G7-I7,0) | K7: =IF(J7>0,About!$C$4-C7,"") | L7: =IF(H7="Undecided","Decide: Lent or Spend",IF(AND(H7="Lent",J7>0),"Waiting for repayment",IF(H7="Lent","Settled","")))
B8: =Ledger!A30 | C8: =Ledger!B30 | D8: =Ledger!J30 | E8: Name only · UPI ref U-6003 | F8: =Ledger!C30 | G8: =Ledger!F30 | H8: Spend | I8: =SUMIFS(Ledger!$F$2:$F$200,Ledger!$H$2:$H$200,"Lent repayment",Ledger!$J$2:$J$200,D8) | J8: =IF(H8="Lent",G8-I8,0) | K8: =IF(J8>0,About!$C$4-C8,"") | L8: =IF(H8="Undecided","Decide: Lent or Spend",IF(AND(H8="Lent",J8>0),"Waiting for repayment",IF(H8="Lent","Settled","")))
B9: =Ledger!A33 | C9: =Ledger!B33 | D9: =Ledger!J33 | E9: Name only · UPI ref U-6004 | F9: =Ledger!C33 | G9: =Ledger!F33 | H9: Undecided | I9: =SUMIFS(Ledger!$F$2:$F$200,Ledger!$H$2:$H$200,"Lent repayment",Ledger!$J$2:$J$200,D9) | J9: =IF(H9="Lent",G9-I9,0) | K9: =IF(J9>0,About!$C$4-C9,"") | L9: =IF(H9="Undecided","Decide: Lent or Spend",IF(AND(H9="Lent",J9>0),"Waiting for repayment",IF(H9="Lent","Settled","")))
B10: =Ledger!A36 | C10: =Ledger!B36 | D10: =Ledger!J36 | E10: Name only · UPI ref U-6005 | F10: =Ledger!C36 | G10: =Ledger!F36 | H10: Spend | I10: =SUMIFS(Ledger!$F$2:$F$200,Ledger!$H$2:$H$200,"Lent repayment",Ledger!$J$2:$J$200,D10) | J10: =IF(H10="Lent",G10-I10,0) | K10: =IF(J10>0,About!$C$4-C10,"") | L10: =IF(H10="Undecided","Decide: Lent or Spend",IF(AND(H10="Lent",J10>0),"Waiting for repayment",IF(H10="Lent","Settled","")))
B11: =Ledger!A40 | C11: =Ledger!B40 | D11: =Ledger!J40 | E11: suresh.p@upi | F11: =Ledger!C40 | G11: =Ledger!F40 | H11: Lent | I11: =SUMIFS(Ledger!$F$2:$F$200,Ledger!$H$2:$H$200,"Lent repayment",Ledger!$J$2:$J$200,D11) | J11: =IF(H11="Lent",G11-I11,0) | K11: =IF(J11>0,About!$C$4-C11,"") | L11: =IF(H11="Undecided","Decide: Lent or Spend",IF(AND(H11="Lent",J11>0),"Waiting for repayment",IF(H11="Lent","Settled","")))
B13: Total lent outstanding | J13: =SUM(J7:J11)
B14: Awaiting your decision | J14: =SUMIFS(G7:G11,H7:H11,"Undecided")

Sheet Regular & EMI
B1: Regular & EMI
B3: Items you define. When a matching SMS arrives its real amount replaces the expected one. No SMS yet is shown, never guessed.
B5: Item | C5: Kind | D5: Expected | E5: Due date | F5: Seen this month | G5: Status | H5: Paid | I5: Progress | J5: Note
B6: Rent | C6: Regular | D6: 14000 | E6: 46298 | F6: =SUMIFS(Ledger!$F$2:$F$200,Ledger!$I$2:$I$200,B6,Ledger!$H$2:$H$200,C6,Ledger!$B$2:$B$200,">="&About!$C$5,Ledger!$B$2:$B$200,"<="&About!$C$6) | G6: =IF(F6>0,"Seen",IF(E6>About!$C$6,"Next month",IF(E6<About!$C$4,"No SMS yet","Expected")))
B7: SIP | C7: Regular | D7: 8000 | E7: 46300 | F7: =SUMIFS(Ledger!$F$2:$F$200,Ledger!$I$2:$I$200,B7,Ledger!$H$2:$H$200,C7,Ledger!$B$2:$B$200,">="&About!$C$5,Ledger!$B$2:$B$200,"<="&About!$C$6) | G7: =IF(F7>0,"Seen",IF(E7>About!$C$6,"Next month",IF(E7<About!$C$4,"No SMS yet","Expected"))) | J7: Investment, not spending on other reports
B8: Claude subscription | C8: Regular | D8: 2400 | E8: 46299 | F8: =SUMIFS(Ledger!$F$2:$F$200,Ledger!$I$2:$I$200,B8,Ledger!$H$2:$H$200,C8,Ledger!$B$2:$B$200,">="&About!$C$5,Ledger!$B$2:$B$200,"<="&About!$C$6) | G8: =IF(F8>0,"Seen",IF(E8>About!$C$6,"Next month",IF(E8<About!$C$4,"No SMS yet","Expected")))
B9: TV EMI | C9: EMI | D9: 5000 | E9: 46303 | F9: =SUMIFS(Ledger!$F$2:$F$200,Ledger!$I$2:$I$200,B9,Ledger!$H$2:$H$200,C9,Ledger!$B$2:$B$200,">="&About!$C$5,Ledger!$B$2:$B$200,"<="&About!$C$6) | G9: =IF(F9>0,"Seen",IF(E9>About!$C$6,"Next month",IF(E9<About!$C$4,"No SMS yet","Expected"))) | H9: ="3 of 12" | I9: =REPT("█",3)&REPT("░",12-3) | J9: On ICICI card
B10: Gym | C10: Regular | D10: 1200 | E10: 46320 | F10: =SUMIFS(Ledger!$F$2:$F$200,Ledger!$I$2:$I$200,B10,Ledger!$H$2:$H$200,C10,Ledger!$B$2:$B$200,">="&About!$C$5,Ledger!$B$2:$B$200,"<="&About!$C$6) | G10: =IF(F10>0,"Seen",IF(E10>About!$C$6,"Next month",IF(E10<About!$C$4,"No SMS yet","Expected"))) | J10: Defined by you, no SMS arrives for it
B11: Term insurance (ICICI Life) | C11: Regular | D11: 1999 | E11: 46339 | F11: =SUMIFS(Ledger!$F$2:$F$200,Ledger!$I$2:$I$200,B11,Ledger!$H$2:$H$200,C11,Ledger!$B$2:$B$200,">="&About!$C$5,Ledger!$B$2:$B$200,"<="&About!$C$6) | G11: =IF(F11>0,"Seen",IF(E11>About!$C$6,"Next month",IF(E11<About!$C$4,"No SMS yet","Expected"))) | J11: Premium notice seen; due date from SMS

Sheet Ledger
A1: ID | B1: Date | C1: Account | D1: Type | E1: Direction | F1: Amount | G1: Kind | H1: Block | I1: Reason | J1: Counterparty / UPI id | K1: UPI ref | L1: Note | M1: Settles card | N1: Counts as spend
A2: L001 | B2: 46296 | C2: HDFC ••7345 | D2: Bank | E2: Credit | F2: 45333 | G2: Salary | H2: Income | I2: Salary | J2: Example Employer | N2: =IF(OR(H2="CC Spend",H2="Bank Spend",H2="Regular",H2="EMI"),IF(E2="Debit",F2,-F2),0)
A3: L002 | B3: 46296 | C3: HDFC ••7345 | D3: Bank | E3: Debit | F3: 12000 | G3: Transfer | H3: Transfer | I3: To own account | J3: Kotak ••2126 | K3: U-1001 | N3: =IF(OR(H3="CC Spend",H3="Bank Spend",H3="Regular",H3="EMI"),IF(E3="Debit",F3,-F3),0)
A4: L003 | B4: 46296 | C4: Kotak ••2126 | D4: Bank | E4: Credit | F4: 12000 | G4: Transfer | H4: Transfer | I4: From own account | J4: HDFC ••7345 | K4: U-1001 | N4: =IF(OR(H4="CC Spend",H4="Bank Spend",H4="Regular",H4="EMI"),IF(E4="Debit",F4,-F4),0)
A5: L004 | B5: 46296 | C5: HDFC ••7345 | D5: Bank | E5: Debit | F5: 5000 | G5: Transfer | H5: Transfer | I5: To own account | J5: Federal ••3268 | K5: U-1002 | N5: =IF(OR(H5="CC Spend",H5="Bank Spend",H5="Regular",H5="EMI"),IF(E5="Debit",F5,-F5),0)
A6: L005 | B6: 46296 | C6: Federal ••3268 | D6: Bank | E6: Credit | F6: 5000 | G6: Transfer | H6: Transfer | I6: From own account | J6: HDFC ••7345 | K6: U-1002 | N6: =IF(OR(H6="CC Spend",H6="Bank Spend",H6="Regular",H6="EMI"),IF(E6="Debit",F6,-F6),0)
A7: L006 | B7: 46297 | C7: HDFC ••7345 | D7: Bank | E7: Debit | F7: 3000 | G7: Transfer | H7: Transfer | I7: To own account | J7: CUB ••1756 | K7: U-1003 | N7: =IF(OR(H7="CC Spend",H7="Bank Spend",H7="Regular",H7="EMI"),IF(E7="Debit",F7,-F7),0)
A8: L007 | B8: 46297 | C8: CUB ••1756 | D8: Bank | E8: Credit | F8: 3000 | G8: Transfer | H8: Transfer | I8: From own account | J8: HDFC ••7345 | K8: U-1003 | N8: =IF(OR(H8="CC Spend",H8="Bank Spend",H8="Regular",H8="EMI"),IF(E8="Debit",F8,-F8),0)
A9: L008 | B9: 46297 | C9: ICICI CC ••9000 | D9: Credit card | E9: Debit | F9: 450 | G9: Purchase | H9: CC Spend | I9: SWIGGY | J9: SWIGGY | K9: U-2001 | N9: =IF(OR(H9="CC Spend",H9="Bank Spend",H9="Regular",H9="EMI"),IF(E9="Debit",F9,-F9),0)
A10: L009 | B10: 46298 | C10: HDFC ••7345 | D10: Bank | E10: Debit | F10: 14000 | G10: Regular | H10: Regular | I10: Rent | J10: Landlord | N10: =IF(OR(H10="CC Spend",H10="Bank Spend",H10="Regular",H10="EMI"),IF(E10="Debit",F10,-F10),0)
A11: L010 | B11: 46298 | C11: Kotak ••2126 | D11: Bank | E11: Debit | F11: 210 | G11: Purchase | H11: Bank Spend | I11: CAFE MOCHA | J11: cafemocha@upi | K11: U-3001 | N11: =IF(OR(H11="CC Spend",H11="Bank Spend",H11="Regular",H11="EMI"),IF(E11="Debit",F11,-F11),0)
A12: L011 | B12: 46299 | C12: ICICI CC ••9000 | D12: Credit card | E12: Debit | F12: 2400 | G12: Regular | H12: Regular | I12: Claude subscription | J12: Anthropic | N12: =IF(OR(H12="CC Spend",H12="Bank Spend",H12="Regular",H12="EMI"),IF(E12="Debit",F12,-F12),0)
A13: L012 | B13: 46300 | C13: HDFC ••7345 | D13: Bank | E13: Debit | F13: 8000 | G13: Regular | H13: Regular | I13: SIP | J13: Example Mutual Fund | N13: =IF(OR(H13="CC Spend",H13="Bank Spend",H13="Regular",H13="EMI"),IF(E13="Debit",F13,-F13),0)
A14: L013 | B14: 46301 | C14: ICICI CC ••9000 | D14: Credit card | E14: Debit | F14: 1299 | G14: Purchase | H14: CC Spend | I14: AMAZON | J14: AMAZON | K14: U-2002 | N14: =IF(OR(H14="CC Spend",H14="Bank Spend",H14="Regular",H14="EMI"),IF(E14="Debit",F14,-F14),0)
A15: L014 | B15: 46302 | C15: SBI CC ••8100 | D15: Credit card | E15: Debit | F15: 2199 | G15: Purchase | H15: CC Spend | I15: MYNTRA | J15: MYNTRA | N15: =IF(OR(H15="CC Spend",H15="Bank Spend",H15="Regular",H15="EMI"),IF(E15="Debit",F15,-F15),0)
A16: L015 | B16: 46303 | C16: ICICI CC ••9000 | D16: Credit card | E16: Debit | F16: 5000 | G16: EMI | H16: EMI | I16: TV EMI | J16: Example Retail | L16: 3 of 12 | N16: =IF(OR(H16="CC Spend",H16="Bank Spend",H16="Regular",H16="EMI"),IF(E16="Debit",F16,-F16),0)
A17: L016 | B17: 46304 | C17: ICICI CC ••9000 | D17: Credit card | E17: Debit | F17: 290 | G17: Purchase | H17: CC Spend | I17: SWASTIK | J17: SWASTIK | K17: U-2003 | N17: =IF(OR(H17="CC Spend",H17="Bank Spend",H17="Regular",H17="EMI"),IF(E17="Debit",F17,-F17),0)
A18: L017 | B18: 46305 | C18: Kotak ••2126 | D18: Bank | E18: Debit | F18: 120 | G18: Purchase | H18: Bank Spend | I18: STATIONERY | J18: stationery@upi | K18: U-3002 | N18: =IF(OR(H18="CC Spend",H18="Bank Spend",H18="Regular",H18="EMI"),IF(E18="Debit",F18,-F18),0)
A19: L018 | B19: 46306 | C19: Federal ••3268 | D19: Bank | E19: Debit | F19: 51 | G19: Purchase | H19: Bank Spend | I19: AUTO FARE | J19: paytmqr-0001@upi | K19: U-3003 | N19: =IF(OR(H19="CC Spend",H19="Bank Spend",H19="Regular",H19="EMI"),IF(E19="Debit",F19,-F19),0)
A20: L019 | B20: 46307 | C20: ICICI CC ••9000 | D20: Credit card | E20: Debit | F20: 2000 | G20: Purchase | H20: CC Spend | I20: FUEL · INDIAN OIL | J20: INDIAN OIL | N20: =IF(OR(H20="CC Spend",H20="Bank Spend",H20="Regular",H20="EMI"),IF(E20="Debit",F20,-F20),0)
A21: L020 | B21: 46307 | C21: Kotak ••2126 | D21: Bank | E21: Debit | F21: 3000 | G21: Person payment | H21: =IF('People & Lent'!H7="Lent","Lent",IF('People & Lent'!H7="Undecided","Undecided","Bank Spend")) | I21: Payment to person | J21: DEEPAK S | K21: U-6001 | L21: =IF('People & Lent'!H7="Undecided","Needs review","") | N21: =IF(OR(H21="CC Spend",H21="Bank Spend",H21="Regular",H21="EMI"),IF(E21="Debit",F21,-F21),0)
A22: L021 | B22: 46309 | C22: SBI CC ••8100 | D22: Credit card | E22: Debit | F22: 410 | G22: Purchase | H22: CC Spend | I22: APOLLO PHARMACY | J22: APOLLO | N22: =IF(OR(H22="CC Spend",H22="Bank Spend",H22="Regular",H22="EMI"),IF(E22="Debit",F22,-F22),0)
A23: L022 | B23: 46310 | C23: ICICI CC ••9000 | D23: Credit card | E23: Debit | F23: 220 | G23: Purchase | H23: CC Spend | I23: UBER | J23: UBER | K23: U-2004 | N23: =IF(OR(H23="CC Spend",H23="Bank Spend",H23="Regular",H23="EMI"),IF(E23="Debit",F23,-F23),0)
A24: L023 | B24: 46311 | C24: Federal ••3268 | D24: Bank | E24: Debit | F24: 185 | G24: Purchase | H24: Bank Spend | I24: VEGETABLE MART | J24: vegmart@upi | K24: U-3004 | N24: =IF(OR(H24="CC Spend",H24="Bank Spend",H24="Regular",H24="EMI"),IF(E24="Debit",F24,-F24),0)
A25: L024 | B25: 46313 | C25: ICICI CC ••9000 | D25: Credit card | E25: Debit | F25: 1326 | G25: Purchase | H25: CC Spend | I25: BIGBASKET | J25: BIGBASKET | K25: U-2005 | N25: =IF(OR(H25="CC Spend",H25="Bank Spend",H25="Regular",H25="EMI"),IF(E25="Debit",F25,-F25),0)
A26: L025 | B26: 46314 | C26: Federal ••3268 | D26: Bank | E26: Debit | F26: 240 | G26: Purchase | H26: Bank Spend | I26: MEDPLUS | J26: medplus@upi | K26: U-3005 | N26: =IF(OR(H26="CC Spend",H26="Bank Spend",H26="Regular",H26="EMI"),IF(E26="Debit",F26,-F26),0)
A27: L026 | B27: 46315 | C27: Kotak ••2126 | D27: Bank | E27: Credit | F27: 1000 | G27: Lent repayment | H27: Lent repayment | I27: Repaid | J27: DEEPAK S | K27: U-6002 | N27: =IF(OR(H27="CC Spend",H27="Bank Spend",H27="Regular",H27="EMI"),IF(E27="Debit",F27,-F27),0)
A28: L027 | B28: 46316 | C28: SBI CC ••8100 | D28: Credit card | E28: Debit | F28: 515 | G28: Purchase | H28: CC Spend | I28: ZOMATO | J28: ZOMATO | N28: =IF(OR(H28="CC Spend",H28="Bank Spend",H28="Regular",H28="EMI"),IF(E28="Debit",F28,-F28),0)
A29: L028 | B29: 46317 | C29: CUB ••1756 | D29: Bank | E29: Debit | F29: 1100 | G29: Purchase | H29: Bank Spend | I29: ELECTRICITY BOARD | J29: EB | K29: U-3006 | N29: =IF(OR(H29="CC Spend",H29="Bank Spend",H29="Regular",H29="EMI"),IF(E29="Debit",F29,-F29),0)
A30: L029 | B30: 46319 | C30: Kotak ••2126 | D30: Bank | E30: Debit | F30: 800 | G30: Person payment | H30: =IF('People & Lent'!H8="Lent","Lent",IF('People & Lent'!H8="Undecided","Undecided","Bank Spend")) | I30: Payment to person | J30: ANITA R | K30: U-6003 | L30: =IF('People & Lent'!H8="Undecided","Needs review","") | N30: =IF(OR(H30="CC Spend",H30="Bank Spend",H30="Regular",H30="EMI"),IF(E30="Debit",F30,-F30),0)
A31: L030 | B31: 46321 | C31: SBI CC ••8100 | D31: Credit card | E31: Debit | F31: 1053 | G31: Purchase | H31: CC Spend | I31: DMART | J31: DMART | N31: =IF(OR(H31="CC Spend",H31="Bank Spend",H31="Regular",H31="EMI"),IF(E31="Debit",F31,-F31),0)
A32: L031 | B32: 46322 | C32: ICICI CC ••9000 | D32: Credit card | E32: Debit | F32: 640 | G32: Purchase | H32: CC Spend | I32: BOOKMYSHOW | J32: BOOKMYSHOW | K32: U-2006 | N32: =IF(OR(H32="CC Spend",H32="Bank Spend",H32="Regular",H32="EMI"),IF(E32="Debit",F32,-F32),0)
A33: L032 | B33: 46323 | C33: Federal ••3268 | D33: Bank | E33: Debit | F33: 2500 | G33: Person payment | H33: =IF('People & Lent'!H9="Lent","Lent",IF('People & Lent'!H9="Undecided","Undecided","Bank Spend")) | I33: Payment to person | J33: MEERA K | K33: U-6004 | L33: =IF('People & Lent'!H9="Undecided","Needs review","") | N33: =IF(OR(H33="CC Spend",H33="Bank Spend",H33="Regular",H33="EMI"),IF(E33="Debit",F33,-F33),0)
A34: L033 | B34: 46324 | C34: Federal ••3268 | D34: Bank | E34: Debit | F34: 120 | G34: Purchase | H34: Bank Spend | I34: TEA STALL | J34: teastall@upi | K34: U-3007 | N34: =IF(OR(H34="CC Spend",H34="Bank Spend",H34="Regular",H34="EMI"),IF(E34="Debit",F34,-F34),0)
A35: L034 | B35: 46324 | C35: Federal ••3268 | D35: Bank | E35: Credit | F35: 22695 | G35: Other credit | H35: Income | I35: Other income · PF advance | J35: Provident fund | L35: Recategorise if needed | N35: =IF(OR(H35="CC Spend",H35="Bank Spend",H35="Regular",H35="EMI"),IF(E35="Debit",F35,-F35),0)
A36: L035 | B36: 46324 | C36: Federal ••3268 | D36: Bank | E36: Debit | F36: 135 | G36: Person payment | H36: =IF('People & Lent'!H10="Lent","Lent",IF('People & Lent'!H10="Undecided","Undecided","Bank Spend")) | I36: Payment to person | J36: RAVI TEJA M | K36: U-6005 | L36: =IF('People & Lent'!H10="Undecided","Needs review","") | N36: =IF(OR(H36="CC Spend",H36="Bank Spend",H36="Regular",H36="EMI"),IF(E36="Debit",F36,-F36),0)
A37: L036 | B37: 46325 | C37: Kotak ••2126 | D37: Bank | E37: Debit | F37: 9261.34 | G37: Card bill | H37: Card bill | I37: CRED payment | J37: CRED | K37: U-4001 | L37: Assigned to ICICI card | M37: ICICI CC ••9000 | N37: =IF(OR(H37="CC Spend",H37="Bank Spend",H37="Regular",H37="EMI"),IF(E37="Debit",F37,-F37),0)
A38: L037 | B38: 46325 | C38: CUB ••1756 | D38: Bank | E38: Debit | F38: 2400 | G38: Transfer | H38: Transfer | I38: To own account | J38: Kotak ••2126 | K38: U-1010 | L38: Credit leg not seen | N38: =IF(OR(H38="CC Spend",H38="Bank Spend",H38="Regular",H38="EMI"),IF(E38="Debit",F38,-F38),0)
A39: L038 | B39: 46325 | C39: CUB ••1756 | D39: Bank | E39: Credit | F39: 500 | G39: Other credit | H39: Unclassified credit | I39: Received from a/c ••0421 | J39: ••0421 | K39: U-5001 | L39: Needs review | N39: =IF(OR(H39="CC Spend",H39="Bank Spend",H39="Regular",H39="EMI"),IF(E39="Debit",F39,-F39),0)
A40: L039 | B40: 46325 | C40: Kotak ••2126 | D40: Bank | E40: Debit | F40: 1500 | G40: Person payment | H40: =IF('People & Lent'!H11="Lent","Lent",IF('People & Lent'!H11="Undecided","Undecided","Bank Spend")) | I40: Payment to person | J40: SURESH P | K40: U-6006 | L40: =IF('People & Lent'!H11="Undecided","Needs review","") | N40: =IF(OR(H40="CC Spend",H40="Bank Spend",H40="Regular",H40="EMI"),IF(E40="Debit",F40,-F40),0)
...

Sheet Review
B1: Needs your attention
B3: Nothing here is hidden or counted as spending or income until you decide.
B5: What | C5: Amount | D5: Detail | E5: Date | F5: Suggested action
B6: Undecided people payment | C6: =Ledger!F33 | D6: =Ledger!J33&" · "&Ledger!C33 | E6: =Ledger!B33 | F6: Mark as Lent or Spend on the People & Lent sheet
B7: Transfer, other leg not seen | C7: =Ledger!F38 | D7: =Ledger!C38&" to "&Ledger!J38 | E7: =Ledger!B38 | F7: Wait for the credit SMS, or confirm the transfer manually
B8: Unclassified credit | C8: =Ledger!F39 | D8: =Ledger!I39&" · "&Ledger!C39 | E8: =Ledger!B39 | F8: Tag as income, lent repayment, refund or own account
B9: Unparsed SMS | D9: 2 messages from an unknown sender format | E9: 46325 | F9: Ignore messages like this, or add a template
B10: Card payment awaiting confirmation | C10: ='Cards & Dues'!G6 | D10: ICICI ••9000 · paid via CRED | E10: 46325 | F10: Clears when the issuer's payment-received SMS arrives

Sheet About
B1: About this workbook
B4: Report as-of date (input) | C4: 46325 | D4: Input. Everything recalculates from this date. The real app uses today in your time zone.
B5: Period start | C5: =DATE(YEAR(C4),MONTH(C4),1) | D5: Calendar month of the as-of date. Weekly and monthly reports use the same builder with another range.
B6: Period end | C6: =EOMONTH(C4,0)
B8: SAMPLE DATA | C8: Every name, amount and reference here is fake. The real export is generated by the app from the ledger.
B9: Total spent | C9: CC Spend + Bank Spend + Regular + EMI, net of refunds. Excludes transfers, card-bill payments, lent and undecided money.
B10: Transfers | C10: Money moved between your own accounts. Counted once, never as income or spend. Both legs stay in the Ledger.
B11: Card bill payments | C11: Paying a card from a bank (e.g. via CRED) settles a liability. The purchases were already counted when charged.
B12: Lent / Undecided | C12: Payments to people. Under the threshold they default to Spend; at or above it they wait for your decision.
B13: Colour meaning | C13: Red = payable soon or overdue. Amber = needs your decision. Green = settled or healthy. Teal = flow of money.
B14: Blue text | C14: Inputs you can edit. Black text is a formula. Do not overwrite formulas.
B15: Assumption | C15: Person-payment threshold of ₹1,000 is an app setting, shown here only as a note. Sample states were chosen by hand.
